Workbook

Sheet Cover
A1: Samvardhana Motherson International Ltd — DCF Valuation
A2: Professional Equity Research / Investment Banking Style Model
A4: Valuation date | B4: 10-Sep-2026 | D4: Project architecture | E4: Project architecture
A5: Latest trading price (₹/share) | B5: =Assumptions!B3 -> 162.71 | D5: Historical financials | E5: Historical financials | F5: 6 years of selected consolidated data
A6: Base-case intrinsic value (₹/share) | B6: =DCF!G15 -> 62.433452 | D6: Forecast | E6: Forecast | F6: 5-year explicit FCFF forecast
A7: Upside / (downside) | B7: =DCF!G15/Assumptions!B3-1 -> -0.61629001 | D7: WACC | E7: WACC | F7: CAPM + peer-derived bottom-up beta
A8: Base-case enterprise value (₹ crore) | B8: =DCF!G10 -> 74274.029 | D8: Valuation | E8: Valuation | F8: Perpetuity-growth DCF + exit-multiple cross-check
A9: Base-case equity value (₹ crore) | B9: =DCF!G13 -> 65895.029 | D9: Scenarios | E9: Scenarios | F9: Dynamic bear / base / bull
A10: Bull value (₹/share) | B10: ='Scenario Analysis'!D8 -> 0.117 | D10: Cross-checks | E10: Cross-checks | F10: Trading comparables + market-implied expectations
A11: Bear value (₹/share) | B11: ='Scenario Analysis'!B8 -> 0.098
A12: Interpretation | B12: Base DCF is below the market price because the market is valuing Motherson on stronger long-term growth/margin execution and a materially higher implied operating multiple than the base-case DCF.

Sheet Assumptions
A1: Key Assumptions — Samvardhana Motherson International Ltd
A2: Item | B2: Value | C2: Units | D2: Type | E2: Rationale | F2: Source / note
A3: Current share price | B3: 162.71 | C3: ₹/share | D3: Input | E3: Observed close used for market-value checks | F3: StockAnalysis / FT, NSE MOTHERSON close/intraday snapshot, 10-Sep-2026
A4: Current market cap | B4: =B3*B15 -> 171731.34 | C4: ₹ crore | D4: Calculated | E4: Market value used for capital structure | F4: Calculated from share price × diluted shares
A5: Risk-free rate | B5: 0.06962 | C5: % | D5: Input | E5: India 10Y government bond yield | F5: India 10Y government bond yield, 9-Sep-2026 close / 10-Sep-2026 snapshot
A6: Observed equity beta | B6: 1.4615 | C6: x | D6: Input | E6: Market-data beta cross-check | F6: FT market-data beta, 10-Sep-2026 snapshot; cross-check only
A7: India equity risk premium | B7: 0.0727 | C7: % | D7: Input | E7: Current country ERP / total equity risk premium | F7: Damodaran current India ERP dataset; refresh before publication
A8: Bottom-up beta used | B8: =WACC!B27 -> 0.91882648 | C8: x | D8: Calculated | E8: Peer-derived median unlevered beta, relevered to Motherson market D/E | F8: See WACC peer build
A9: Pre-tax cost of debt | B9: 0.075 | C9: % | D9: Analyst assumption | E9: Anchored to investment-grade / AAA ratings | F9: Analyst assumption anchored to investment-grade borrowing economics
A10: Normalized tax rate | B10: 0.274 | C10: % | D10: Analyst assumption | E10: Normalized forecast effective rate | F10: Normalized forecast effective rate
A11: Terminal growth | B11: 0.04 | C11: % | D11: Analyst assumption | E11: Mature long-run nominal growth, below WACC | F11: Long-run nominal growth assumption; sensitivity tested
A12: D&A / revenue | B12: 0.037 | C12: % | D12: Analyst assumption | E12: Asset intensity stays broadly stable | F12: Forecast assumption
A13: CapEx / revenue | B13: 0.045 | C13: % | D13: Analyst assumption | E13: Maintenance + growth investment | F13: Forecast assumption; FY27 guidance is ~₹6,000cr ±10%
A14: NWC / revenue | B14: 0.035 | C14: % | D14: Analyst assumption | E14: Explicit operating working-capital driver | F14: Forecast assumption
A15: Diluted shares outstanding | B15: 1055.4443 | C15: crore | F15: Used consistently for market cap and per-share valuation
A16: Market-implied EV / FY26 EBITDA | B16: =('Historical Financials'!G14+B4-'Historical Financials'!G15)/'Historical Financials'!G5 -> 14.968033 | C16: x | F16: Calculated from market cap + FY26 borrowings − FY26 cash, divided by FY26 EBITDA
A17: Year | B17: FY27E | C17: FY28E | D17: FY29E | E17: FY30E | F17: FY31E
A18: Base Forecast Inputs | B18: 0.1 | C18: 0.1 | D18: 0.09 | E18: 0.08 | F18: 0.07
A19: Year | B19: FY27E | C19: FY28E | D19: FY29E | E19: FY30E | F19: FY31E
A20: Revenue growth | B20: 0.1 | C20: 0.1 | D20: 0.09 | E20: 0.08 | F20: 0.07
A21: EBITDA margin | B21: 0.102 | C21: 0.104 | D21: 0.106 | E21: 0.108 | F21: 0.11
A22: D&A / revenue | B22: 0.037 | C22: 0.037 | D22: 0.037 | E22: 0.037 | F22: 0.037
A23: CapEx / revenue | B23: 0.045 | C23: 0.045 | D23: 0.045 | E23: 0.045 | F23: 0.045
A24: NWC / revenue | B24: 0.035 | C24: 0.035 | D24: 0.035 | E24: 0.035 | F24: 0.035
A25: Terminal growth | B25: 0.04 | C25: 0.04 | D25: 0.04 | E25: 0.04 | F25: 0.04

Sheet Historical Financials
A1: Historical Financials — Consolidated ₹ crore
A2: Metric | B2: FY21 | C2: FY22 | D2: FY23 | E2: FY24 | F2: FY25 | G2: FY26 | H2: Source / note
A3: Revenue | B3: 57370 | C3: 63536 | D3: 78701 | E3: 98692 | F3: 113663 | G3: 126104 | H3: Screener / FY26 official results
A4: Revenue growth | C4: 0.1075 | D4: 0.0813 | E4: 0.2536 | F4: 0.1517 | G4: 0.1094 | H4: Calculated
A5: EBITDA / operating profit proxy | B5: 4370 | C5: 4476 | D5: 6164 | E5: 9322 | F5: 10760 | G5: 12033 | H5: Motherson FY26 results presentation / audited results
A6: EBITDA margin | B6: 0.0762 | C6: 0.0704 | D6: 0.0783 | E6: 0.0945 | F6: 0.0946 | G6: =G5/G3 -> 0.09542124 | H6: Calculated
A7: PAT | B7: 1569 | C7: 1182 | D7: 1670 | E7: 3020 | F7: 4146 | G7: 4086 | H7: Screener / FY26 official results
A8: EPS (₹) | B8: 1.46 | C8: 0.86 | D8: 1.47 | E8: 2.67 | F8: 3.6 | G8: 3.66 | H8: Screener / FY26 official results
A9: Operating cash flow | B9: 5051 | C9: 2463 | D9: 4643 | E9: 7569 | F9: 6286 | G9: 11284 | H9: FY26 official results / cash-flow statement
A10: CapEx | B10: 1894 | C10: 2312 | D10: 2245 | E10: 6662 | F10: 4862 | G10: 6054 | H10: Cash outflow proxy; FY26 official
A11: Trade receivables | B11: 5693 | C11: 6573 | D11: 8514 | E11: 15637 | F11: 17431 | G11: 19881 | H11: Moneycontrol FY21-FY25; FY26 official
A12: Inventory | B12: 4996 | C12: 6442 | D12: 7823 | E12: 9139 | F12: 10787 | G12: 12647 | H12: Moneycontrol FY21-FY25; FY26 official
A13: Trade payables | B13: 11141 | C13: 11360 | D13: 14136 | E13: 22617 | F13: 23669 | G13: 28165 | H13: Moneycontrol FY21-FY25; FY26 official
A14: Total borrowings | B14: 10663 | C14: 12761 | D14: 12166 | E14: 17351 | F14: 14644 | G14: 15895 | H14: Moneycontrol FY21-FY25; FY26 official
A15: Cash & equivalents | G15: 7516 | H15: FY26 audited balance sheet
A16: Net working capital | B16: =B11+B12-B13 -> -452 | C16: =C11+C12-C13 -> 1655 | D16: =D11+D12-D13 -> 2201 | E16: =E11+E12-E13 -> 2159 | F16: =F11+F12-F13 -> 4549 | G16: =G11+G12-G13 -> 4363 | H16: Operating NWC = trade receivables + inventory - trade payables

Sheet Income Statement
A1: Income Statement — Historical ₹ crore
A2: Metric | B2: FY21 | C2: FY22 | D2: FY23 | E2: FY24 | F2: FY25 | G2: FY26 | H2: Comment
A3: Revenue | B3: 57370 | C3: 63536 | D3: 78701 | E3: 98692 | F3: 113663 | G3: 126104 | H3: Revenue accelerated materially through FY24-FY26
A4: Revenue growth | C4: 0.1075 | D4: 0.0813 | E4: 0.2536 | F4: 0.1517 | G4: 0.1094 | H4: Growth includes acquisitions and mix
A5: EBITDA | B5: 4370 | C5: 4476 | D5: 6164 | E5: 9322 | F5: 10760 | G5: 12033 | H5: Reported consolidated EBITDA per FY26 results presentation
A6: EBITDA margin | B6: 0.0762 | C6: 0.0704 | D6: 0.0783 | E6: 0.0945 | F6: 0.0946 | G6: =G5/G3 -> 0.09542124 | H6: Margin improved from ~7% to ~10%
A7: D&A | B7: 1800 | C7: 2000 | D7: 2400 | E7: 3810 | F7: 4493 | G7: 5133.85 | H7: FY26 D&A = depreciation ₹4,469.57cr + amortisation ₹664.28cr
A8: EBIT | B8: 2570 | C8: 2476 | D8: 3764 | E8: 5512 | F8: 6267 | G8: =G5-G7 -> 6899.15 | H8: EBIT = reported EBITDA less D&A
A9: PBT | B9: 1613 | C9: 1424 | D9: 2405 | E9: 3840 | F9: 5261 | G9: 5625 | H9: Reported / rounded
A10: Tax | F10: 1116 | G10: 1539 | H10: Reported where available
A11: PAT | B11: 1569 | C11: 1182 | D11: 1670 | E11: 3020 | F11: 4146 | G11: 4086 | H11: Reported / rounded
A12: EPS (₹) | B12: 1.46 | C12: 0.86 | D12: 1.47 | E12: 2.67 | F12: 3.6 | G12: 3.66 | H12: Reported / rounded
A14: Normalization
A15: FY26 includes a reported exceptional consolidated expense of ₹414 crore. No adjustment is made to the base case, as the forecast starts from reported FY26 operating economics and does not assume this item is recurring.
A16: Financing costs are excluded from FCFF and reflected through WACC to avoid double counting.

Sheet Balance Sheet
A1: Balance Sheet / Working Capital — Selected Items ₹ crore
A2: Metric | B2: FY21 | C2: FY22 | D2: FY23 | E2: FY24 | F2: FY25 | G2: FY26 | H2: Comment
A3: Trade receivables | B3: 5693 | C3: 6573 | D3: 8514 | E3: 15637 | F3: 17431 | G3: 19881
A4: Inventory | B4: 4996 | C4: 6442 | D4: 7823 | E4: 9139 | F4: 10787 | G4: 12647
A5: Trade payables | B5: 11141 | C5: 11360 | D5: 14136 | E5: 22617 | F5: 23669 | G5: 28165
A6: NWC | B6: =B3+B4-B5 -> -452 | C6: =C3+C4-C5 -> 1655 | D6: =D3+D4-D5 -> 2201 | E6: =E3+E4-E5 -> 2159 | F6: =F3+F4-F5 -> 4549 | G6: =G3+G4-G5 -> 4363 | H6: AR + inventory - AP
A7: Total borrowings | B7: 10663 | C7: 12761 | D7: 12166 | E7: 17351 | F7: 14644 | G7: 15895 | H7: FY26 official
A8: Cash | G8: 7516 | H8: FY26 official
A9: Net debt | G9: =G7-G8 -> 8379 | H9: Borrowings less cash
A10: Debt / EBITDA | G10: =G7/'Historical Financials'!G5 -> 1.3209507 | H10: Latest-year leverage check
A11: Current ratio | G11: 1.06 | H11: FY26 official
A12: DSO (days) | B12: 36.2 | C12: 37.8 | D12: 39.5 | E12: 57.9 | F12: 56 | G12: 57.5 | H12: AR / revenue × 365
A13: DIO (days) | B13: 31.8 | C13: 37 | D13: 36.3 | E13: 33.8 | F13: 34.6 | G13: 36.6 | H13: Inventory / revenue × 365
A14: DPO (days) | B14: 70.9 | C14: 65.3 | D14: 65.6 | E14: 83.7 | F14: 76 | G14: 81.5 | H14: AP / revenue × 365
A16: Working-capital interpretation
A17: Receivables and inventory have grown with the business; payables also provide a meaningful operating funding source.
A18: The forecast uses explicit NWC/revenue assumptions rather than a blind percentage-of-sales plug.

Sheet Cash Flow
A1: Cash Flow — Historical ₹ crore
A2: Metric | B2: FY21 | C2: FY22 | D2: FY23 | E2: FY24 | F2: FY25 | G2: FY26 | H2: Comment
A3: Operating cash flow | B3: 5051 | C3: 2463 | D3: 4643 | E3: 7569 | F3: 6286 | G3: 11284 | H3: FY26 official results
A4: CapEx | B4: 1894 | C4: 2312 | D4: 2245 | E4: 6662 | F4: 4862 | G4: 6054 | H4: PPE/intangible cash outflow proxy
A5: OCF less CapEx | B5: 3157 | C5: 151 | D5: 2398 | E5: 907 | F5: 1424 | G5: =G3-G4 -> 5230 | H5: Cash-flow proxy, not FCFF
A6: Net financing cash flow | B6: -2098 | C6: -1217 | D6: -2734 | E6: 1281 | F6: -2551 | G6: -3275 | H6: FY26 official
A7: OCF / PAT | B7: 3.22 | C7: 2.08 | D7: 2.78 | E7: 2.51 | F7: 1.52 | G7: 1.54 | H7: Cash conversion
A9: Cash-flow interpretation
A10: Cash generation improved materially versus the weak FY22 year, but reinvestment and working-capital intensity make reported OCF a poor substitute for FCFF in a forward DCF.
A11: FCFF therefore starts from EBIT/NOPAT, adds non-cash D&A, and subtracts CapEx plus change in NWC.
A12: This separation is important because financing flows are not part of operating FCFF.

Sheet Operating Drivers
A1: Operating Drivers — Historical & Forecast
A2: Driver | B2: FY21 | C2: FY22 | D2: FY23 | E2: FY24 | F2: FY25 | G2: FY26 | H2: Forecast rationale
A3: Revenue growth | C3: 0.1075 | D3: 0.0813 | E3: 0.2536 | F3: 0.1517 | G3: 0.1094 | H3: Base case tapers to 7% by FY31E
A4: EBITDA margin | B4: 0.0762 | C4: 0.0704 | D4: 0.0783 | E4: 0.0945 | F4: 0.0946 | G4: 0.0961 | H4: Modest expansion to 11.0%
A5: D&A / revenue | B5: 0.0314 | C5: 0.0315 | D5: 0.0305 | E5: 0.0386 | F5: 0.0395 | G5: 0.0396 | H5: Forecast 3.7%
A6: CapEx / revenue | B6: 0.033 | C6: 0.0364 | D6: 0.0285 | E6: 0.0676 | F6: 0.0428 | G6: 0.048 | H6: Forecast 4.5%
A7: NWC / revenue | B7: -0.0079 | C7: 0.026 | D7: 0.028 | E7: 0.0219 | F7: 0.04 | G7: 0.0346 | H7: Forecast 3.5%
A9: Driver logic
A10: Revenue
A11: Margin
A12: CapEx
A13: Working capital

Sheet Forecast
A1: 5-Year Operating Forecast — Base Case ₹ crore
A2: Metric | B2: FY26A | C2: FY27E | D2: FY28E | E2: FY29E | F2: FY30E | G2: FY31E | H2: Formula / rationale
A3: Revenue | B3: 126103.67 | C3: =B3*(1+Assumptions!B20) -> 138714.04 | D3: =C3*(1+Assumptions!C20) -> 152585.44 | E3: =D3*(1+Assumptions!D20) -> 166318.13 | F3: =E3*(1+Assumptions!E20) -> 179623.58 | G3: =F3*(1+Assumptions!F20) -> 192197.23
A4: Revenue growth | C4: =Assumptions!B20 -> 0.1 | D4: =Assumptions!C20 -> 0.1 | E4: =Assumptions!D20 -> 0.09 | F4: =Assumptions!E20 -> 0.08 | G4: =Assumptions!F20 -> 0.07
A5: EBITDA | B5: ='Historical Financials'!G5 -> 12033 | C5: =C3*Assumptions!B21 -> 14148.832 | D5: =D3*Assumptions!C21 -> 15868.886 | E5: =E3*Assumptions!D21 -> 17629.722 | F5: =F3*Assumptions!E21 -> 19399.347 | G5: =G3*Assumptions!F21 -> 21141.695 | H5: FY26A reported EBITDA; forecast uses explicit EBITDA-margin assumptions
A6: EBITDA margin | B6: =B5/B3 -> 0.095421489 | C6: =C5/C3 -> 0.102 | D6: =D5/D3 -> 0.104 | E6: =E5/E3 -> 0.106 | F6: =F5/F3 -> 0.108 | G6: =G5/G3 -> 0.11
A7: D&A | B7: 5133.85 | C7: =C3*Assumptions!B22 -> 5132.4194 | D7: =D3*Assumptions!C22 -> 5645.6613 | E7: =E3*Assumptions!D22 -> 6153.7708 | F7: =F3*Assumptions!E22 -> 6646.0725 | G7: =G3*Assumptions!F22 -> 7111.2976 | H7: FY26 actual D&A from audited consolidated results
A8: EBIT | B8: =B5-B7 -> 6899.15 | C8: =C5-C7 -> 9016.4124 | D8: =D5-D7 -> 10223.225 | E8: =E5-E7 -> 11475.951 | F8: =F5-F7 -> 12753.274 | G8: =G5-G7 -> 14030.398
A9: Tax rate | B9: =Assumptions!B10 -> 0.274 | C9: =Assumptions!$B$10 -> 0.274 | D9: =Assumptions!$B$10 -> 0.274 | E9: =Assumptions!$B$10 -> 0.274 | F9: =Assumptions!$B$10 -> 0.274 | G9: =Assumptions!$B$10 -> 0.274
A10: NOPAT | B10: =B8*(1-B9) -> 5008.7829 | C10: =C8*(1-C9) -> 6545.9154 | D10: =D8*(1-D9) -> 7422.061 | E10: =E8*(1-E9) -> 8331.5404 | F10: =F8*(1-F9) -> 9258.8771 | G10: =G8*(1-G9) -> 10186.069
A11: CapEx | B11: 6054 | C11: =C3*Assumptions!B23 -> 6242.1317 | D11: =D3*Assumptions!C23 -> 6866.3448 | E11: =E3*Assumptions!D23 -> 7484.3159 | F11: =F3*Assumptions!E23 -> 8083.0611 | G11: =G3*Assumptions!F23 -> 8648.8754 | H11: Cash outflow proxy; FY27 capex guidance ~₹6,000cr ±10%
A12: NWC | B12: ='Historical Financials'!G16 -> 4363 | C12: =C3*Assumptions!B24 -> 4854.9913 | D12: =D3*Assumptions!C24 -> 5340.4904 | E12: =E3*Assumptions!D24 -> 5821.1346 | F12: =F3*Assumptions!E24 -> 6286.8253 | G12: =G3*Assumptions!F24 -> 6726.9031 | H12: FY26A operating NWC; forecast NWC = % of revenue
A13: Change in NWC | B13: 0 | C13: =C12-B12 -> 491.9913 | D13: =D12-C12 -> 485.49913 | E13: =E12-D12 -> 480.64414 | F13: =F12-E12 -> 465.69077 | G13: =G12-F12 -> 440.07777
A14: FCFF | C14: =C10+C7-C11-C13 -> 4944.2118 | D14: =D10+D7-D11-D13 -> 5715.8784 | E14: =E10+E7-E11-E13 -> 6520.3512 | F14: =F10+F7-F11-F13 -> 7356.1977 | G14: =G10+G7-G11-G13 -> 8208.4132
A15: FCFF margin | C15: =C14/C3 -> 0.035643197 | D15: =D14/D3 -> 0.037460182 | E15: =E14/E3 -> 0.039204092 | F15: =F14/F3 -> 0.040953407 | G15: =G14/G3 -> 0.04270828

Sheet FCFF
A1: FCFF Build — Base Case ₹ crore
A2: Bridge | B2: FY27E | C2: FY28E | D2: FY29E | E2: FY30E | F2: FY31E | G2: Definition
A3: Revenue | B3: =Forecast!C3 -> 138714.04 | C3: =Forecast!D3 -> 152585.44 | D3: =Forecast!E3 -> 166318.13 | E3: =Forecast!F3 -> 179623.58 | F3: =Forecast!G3 -> 192197.23
A4: EBITDA | B4: =Forecast!C5 -> 14148.832 | C4: =Forecast!D5 -> 15868.886 | D4: =Forecast!E5 -> 17629.722 | E4: =Forecast!F5 -> 19399.347 | F4: =Forecast!G5 -> 21141.695
A5: D&A | B5: =Forecast!C7 -> 5132.4194 | C5: =Forecast!D7 -> 5645.6613 | D5: =Forecast!E7 -> 6153.7708 | E5: =Forecast!F7 -> 6646.0725 | F5: =Forecast!G7 -> 7111.2976
A6: EBIT | B6: =Forecast!C8 -> 9016.4124 | C6: =Forecast!D8 -> 10223.225 | D6: =Forecast!E8 -> 11475.951 | E6: =Forecast!F8 -> 12753.274 | F6: =Forecast!G8 -> 14030.398
A7: Tax | B7: =Forecast!C9 -> 0.274 | C7: =Forecast!D9 -> 0.274 | D7: =Forecast!E9 -> 0.274 | E7: =Forecast!F9 -> 0.274 | F7: =Forecast!G9 -> 0.274
A8: NOPAT | B8: =Forecast!C10 -> 6545.9154 | C8: =Forecast!D10 -> 7422.061 | D8: =Forecast!E10 -> 8331.5404 | E8: =Forecast!F10 -> 9258.8771 | F8: =Forecast!G10 -> 10186.069
A9: + D&A | B9: =Forecast!C7 -> 5132.4194 | C9: =Forecast!D7 -> 5645.6613 | D9: =Forecast!E7 -> 6153.7708 | E9: =Forecast!F7 -> 6646.0725 | F9: =Forecast!G7 -> 7111.2976
A10: - CapEx | B10: =Forecast!C11 -> 6242.1317 | C10: =Forecast!D11 -> 6866.3448 | D10: =Forecast!E11 -> 7484.3159 | E10: =Forecast!F11 -> 8083.0611 | F10: =Forecast!G11 -> 8648.8754
A11: - Change in NWC | B11: =Forecast!C13 -> 491.9913 | C11: =Forecast!D13 -> 485.49913 | D11: =Forecast!E13 -> 480.64414 | E11: =Forecast!F13 -> 465.69077 | F11: =Forecast!G13 -> 440.07777
A12: FCFF | B12: =Forecast!C14 -> 4944.2118 | C12: =Forecast!D14 -> 5715.8784 | D12: =Forecast!E14 -> 6520.3512 | E12: =Forecast!F14 -> 7356.1977 | F12: =Forecast!G14 -> 8208.4132
A14: FCFF formula
A15: Why FCFF
A16: Financing consistency
A17: Terminal check

Sheet WACC
A1: WACC — First Principles + Peer-Derived Bottom-Up Beta
A2: Item | B2: Value | C2: Formula / approach | D2: Units | E2: Source / note | F2: Type
A3: Risk-free rate | B3: =Assumptions!B5 -> 0.06962 | C3: 10Y India government yield | D3: % | E3: India 10Y government yield, 9-Sep-2026 | F3: Input
A4: Observed beta | B4: =Assumptions!B6 -> 1.4615 | C4: Market beta | D4: x | E4: Observed market beta cross-check; FT, 10-Sep-2026 | F4: Input
A5: Equity risk premium | B5: =Assumptions!B7 -> 0.0727 | C5: India ERP | D5: % | E5: Damodaran India ERP | F5: Input
A6: Observed CAPM cost of equity | B6: =B3+B4*B5 -> 0.17587105 | C6: Rf + observed beta × ERP | D6: % | E6: Observed-beta CAPM cross-check | F6: Calculated
A7: Peer-derived unlevered beta | B7: =B27 -> 0.91882648 | C7: Median of peer unlevered betas | D7: x | E7: Analyst normalization; not a sourced market fact | F7: Calculated
A8: Primary cost of equity | B8: =B3+B7*B5 -> 0.13641869 | C8: Rf + bottom-up beta × ERP | D8: % | E8: Primary WACC input | F8: Calculated
A9: Pre-tax cost of debt | B9: =Assumptions!B9 -> 0.075 | C9: Borrowing economics | D9: % | E9: Ratings + borrowing profile | F9: Analyst assumption
A10: Tax rate | B10: =Assumptions!B10 -> 0.274 | C10: Normalized | D10: % | E10: Assumption | F10: Input
A11: After-tax cost of debt | B11: =B9*(1-B10) -> 0.05445 | C11: Kd × (1-tax) | D11: % | E11: Calculated | F11: Calculated
A12: Market equity | B12: =Assumptions!B4 -> 171731.34 | C12: Current market cap | D12: ₹ crore | E12: Market equity at 10-Sep-2026 price | F12: Input
A13: Debt | B13: ='Historical Financials'!G14 -> 15895 | C13: Borrowings excluding leases | D13: ₹ crore | E13: FY26 borrowings; linked to Historical Financials | F13: Input
A14: Equity weight | B14: =B12/(B12+B13) -> 0.91528375 | C14: E/(D+E) | D14: % | E14: Calculated | F14: Calculated
A15: Debt weight | B15: =B13/(B12+B13) -> 0.084716252 | C15: D/(D+E) | D15: % | E15: Calculated | F15: Calculated
A16: WACC | B16: =B14*B8+B15*B11 -> 0.12947461 | C16: E wt × CoE + D wt × Kd × (1-tax) | D16: % | E16: Primary discount rate | F16: Calculated
A18: WACC judgment
A19: Peer | B19: Levered beta | C19: Debt/Equity | D19: Tax rate | E19: Unlevered beta | F19: Source
A20: Uno Minda | B20: 1.1579 | C20: 0.38 | D20: 0.25 | E20: =B20/(1+(1-D20)*C20) -> 0.90108949 | F20: FT Sep-9-2026 beta; StockAnalysis FY26 D/E
A21: Aptiv | B21: 1.33 | C21: 0.65 | D21: 0.25 | E21: =B21/(1+(1-D21)*C21) -> 0.89411765 | F21: StockAnalysis Sep-9-2026 beta; FY26/current D/E
A22: Lear | B22: 1.27 | C22: 0.66 | D22: 0.1907 | E22: =B22/(1+(1-D22)*C22) -> 0.82782644 | F22: StockAnalysis Sep-4/10-2026 beta; current D/E and effective tax
A23: Forvia | B23: 1.65 | C23: 2.55 | D23: 0.25 | E23: =B23/(1+(1-D23)*C23) -> 0.56652361 | F23: StockAnalysis Sep-4-2026 beta; current D/E
A24: Median | E24: =MEDIAN(E20:E23) -> 0.86097204 | F24: Calculated
A26: Motherson market D/E | B26: =B13/B12 -> 0.092557366 | C26: Debt / market equity | F26: Calculated
A27: Relevered bottom-up beta | B27: =E24*(1+(1-B10)*B26) -> 0.91882648 | C27: Median unlevered beta × [1 + (1-tax) × Motherson D/E] | F27: Calculated
A29: Method note | B29: Peer betas are unlevered using Hamada-style adjustment and relevered to Motherson's market-value D/E. This replaces the prior 0.85 analyst assumption.

Sheet DCF
A1: DCF Valuation — Base Case ₹ crore except per share
A2: Metric | B2: FY27E | C2: FY28E | D2: FY29E | E2: FY30E | F2: FY31E | G2: Output
A3: FCFF | B3: =FCFF!B12 -> 4944.2118 | C3: =FCFF!C12 -> 5715.8784 | D3: =FCFF!D12 -> 6520.3512 | E3: =FCFF!E12 -> 7356.1977 | F3: =FCFF!F12 -> 8208.4132
A4: Discount factor | B4: =1/(1+WACC!$B$16)^1 -> 0.8853674 | C4: =1/(1+WACC!$B$16)^2 -> 0.78387544 | D4: =1/(1+WACC!$B$16)^3 -> 0.69401777 | E4: =1/(1+WACC!$B$16)^4 -> 0.61446071 | F4: =1/(1+WACC!$B$16)^5 -> 0.54402348
A5: PV of FCFF | B5: =B3*B4 -> 4377.444 | C5: =C3*C4 -> 4480.5367 | D5: =D3*D4 -> 4525.2396 | E5: =E3*E4 -> 4520.0944 | F5: =F3*F4 -> 4465.5696
A7: Terminal growth | G7: =Assumptions!B11 -> 0.04
A8: Terminal value | G8: =F3*(1+G7)/(WACC!$B$16-G7) -> 95409.751
A9: PV of terminal value | G9: =G8*F4 -> 51905.145
A10: Enterprise value | G10: =SUM(B5:F5)+G9 -> 74274.029
A11: Less: debt | G11: =WACC!B13 -> 15895
A12: Add: cash | G12: ='Historical Financials'!G15 -> 7516
A13: Equity value | G13: =G10-G11+G12 -> 65895.029
A14: Shares outstanding (crore) | G14: =Assumptions!B15 -> 1055.4443
A15: Intrinsic value / share | G15: =G13/G14 -> 62.433452
A16: Market price | G16: =Assumptions!B3 -> 162.71
A17: DCF discount / (premium) to market | G17: =G15/G16-1 -> -0.61629001
A18: Market-implied EV / FY26 EBITDA | B18: =Assumptions!B16 -> 14.968033 | D18: Market-implied multiple at valuation date; cross-check only | G18: =Assumptions!B16 -> 14.968033
A19: Interpretation | B19: =Forecast!G5 -> 21141.695 | C19: ₹ crore | G19: Base DCF uses a lower sustainable operating valuation than the market-implied FY26 multiple; the gap is an expectations / execution issue, not a model error.
A20: Terminal EV | B20: =B18*B19 -> 316449.59 | C20: ₹ crore
A21: Exit multiple cross-check | B21: =(B20-WACC!B13+'Historical Financials'!G15)/G14 -> 291.88712 | C21: ₹/share | G21: Non-primary sanity check only
A22: Exit EBITDA multiple | B22: 9.5 | D22: Illustrative exit EBITDA multiple; analyst cross-check only
A23: Terminal EBITDA | B23: =Forecast!G5 -> 21141.695 | C23: ₹ crore
A24: Terminal EV | B24: =B22*B23 -> 200846.11 | C24: ₹ crore
A25: Implied equity value / share | B25: =(B24-WACC!B13+'Historical Financials'!G15)/G14 -> 182.35649 | C25: ₹/share

Sheet Sensitivity
A1: DCF Sensitivity — Intrinsic Value / Share (₹)
A3: WACC \ Terminal g | B3: 0.02 | C3: 0.025 | D3: 0.03 | E3: 0.035 | F3: 0.04 | H3: Reference | I3: Value
A4: 0.1 | B4: =(DCF!$B$3/(1+$A4)^1+DCF!$C$3/(1+$A4)^2+DCF!$D$3/(1+$A4)^3+DCF!$E$3/(1+$A4)^4+DCF!$F$3/(1+$A4)^5+DCF!$F$3*(1+B$3)/($A4-B$3)/(1+$A4)^5-WACC!$B$13+'Historical Financials'!G15)/DCF!$G$14 -> 76.596685 | C4: =(DCF!$B$3/(1+$A4)^1+DCF!$C$3/(1+$A4)^2+DCF!$D$3/(1+$A4)^3+DCF!$E$3/(1+$A4)^4+DCF!$F$3/(1+$A4)^5+DCF!$F$3*(1+C$3)/($A4-C$3)/(1+$A4)^5-WACC!$B$13+'Historical Financials'!G15)/DCF!$G$14 -> 81.023302 | D4: =(DCF!$B$3/(1+$A4)^1+DCF!$C$3/(1+$A4)^2+DCF!$D$3/(1+$A4)^3+DCF!$E$3/(1+$A4)^4+DCF!$F$3/(1+$A4)^5+DCF!$F$3*(1+D$3)/($A4-D$3)/(1+$A4)^5-WACC!$B$13+'Historical Financials'!G15)/DCF!$G$14 -> 86.082292 | E4: =(DCF!$B$3/(1+$A4)^1+DCF!$C$3/(1+$A4)^2+DCF!$D$3/(1+$A4)^3+DCF!$E$3/(1+$A4)^4+DCF!$F$3/(1+$A4)^5+DCF!$F$3*(1+E$3)/($A4-E$3)/(1+$A4)^5-WACC!$B$13+'Historical Financials'!G15)/DCF!$G$14 -> 91.919589 | F4: =(DCF!$B$3/(1+$A4)^1+DCF!$C$3/(1+$A4)^2+DCF!$D$3/(1+$A4)^3+DCF!$E$3/(1+$A4)^4+DCF!$F$3/(1+$A4)^5+DCF!$F$3*(1+F$3)/($A4-F$3)/(1+$A4)^5-WACC!$B$13+'Historical Financials'!G15)/DCF!$G$14 -> 98.729769 | H4: Base case | I4: =DCF!G15 -> 62.433452
A5: 0.11 | B5: =(DCF!$B$3/(1+$A5)^1+DCF!$C$3/(1+$A5)^2+DCF!$D$3/(1+$A5)^3+DCF!$E$3/(1+$A5)^4+DCF!$F$3/(1+$A5)^5+DCF!$F$3*(1+B$3)/($A5-B$3)/(1+$A5)^5-WACC!$B$13+'Historical Financials'!G15)/DCF!$G$14 -> 66.708449 | C5: =(DCF!$B$3/(1+$A5)^1+DCF!$C$3/(1+$A5)^2+DCF!$D$3/(1+$A5)^3+DCF!$E$3/(1+$A5)^4+DCF!$F$3/(1+$A5)^5+DCF!$F$3*(1+C$3)/($A5-C$3)/(1+$A5)^5-WACC!$B$13+'Historical Financials'!G15)/DCF!$G$14 -> 70.056874 | D5: =(DCF!$B$3/(1+$A5)^1+DCF!$C$3/(1+$A5)^2+DCF!$D$3/(1+$A5)^3+DCF!$E$3/(1+$A5)^4+DCF!$F$3/(1+$A5)^5+DCF!$F$3*(1+D$3)/($A5-D$3)/(1+$A5)^5-WACC!$B$13+'Historical Financials'!G15)/DCF!$G$14 -> 73.823852 | E5: =(DCF!$B$3/(1+$A5)^1+DCF!$C$3/(1+$A5)^2+DCF!$D$3/(1+$A5)^3+DCF!$E$3/(1+$A5)^4+DCF!$F$3/(1+$A5)^5+DCF!$F$3*(1+E$3)/($A5-E$3)/(1+$A5)^5-WACC!$B$13+'Historical Financials'!G15)/DCF!$G$14 -> 78.093093 | F5: =(DCF!$B$3/(1+$A5)^1+DCF!$C$3/(1+$A5)^2+DCF!$D$3/(1+$A5)^3+DCF!$E$3/(1+$A5)^4+DCF!$F$3/(1+$A5)^5+DCF!$F$3*(1+F$3)/($A5-F$3)/(1+$A5)^5-WACC!$B$13+'Historical Financials'!G15)/DCF!$G$14 -> 82.972227 | H5: Bear reference | I5: ='Scenario Analysis'!B8 -> 0.098
A6: 0.12 | B6: =(DCF!$B$3/(1+$A6)^1+DCF!$C$3/(1+$A6)^2+DCF!$D$3/(1+$A6)^3+DCF!$E$3/(1+$A6)^4+DCF!$F$3/(1+$A6)^5+DCF!$F$3*(1+B$3)/($A6-B$3)/(1+$A6)^5-WACC!$B$13+'Historical Financials'!G15)/DCF!$G$14 -> 58.813283 | C6: =(DCF!$B$3/(1+$A6)^1+DCF!$C$3/(1+$A6)^2+DCF!$D$3/(1+$A6)^3+DCF!$E$3/(1+$A6)^4+DCF!$F$3/(1+$A6)^5+DCF!$F$3*(1+C$3)/($A6-C$3)/(1+$A6)^5-WACC!$B$13+'Historical Financials'!G15)/DCF!$G$14 -> 61.41463 | D6: =(DCF!$B$3/(1+$A6)^1+DCF!$C$3/(1+$A6)^2+DCF!$D$3/(1+$A6)^3+DCF!$E$3/(1+$A6)^4+DCF!$F$3/(1+$A6)^5+DCF!$F$3*(1+D$3)/($A6-D$3)/(1+$A6)^5-WACC!$B$13+'Historical Financials'!G15)/DCF!$G$14 -> 64.305015 | E6: =(DCF!$B$3/(1+$A6)^1+DCF!$C$3/(1+$A6)^2+DCF!$D$3/(1+$A6)^3+DCF!$E$3/(1+$A6)^4+DCF!$F$3/(1+$A6)^5+DCF!$F$3*(1+E$3)/($A6-E$3)/(1+$A6)^5-WACC!$B$13+'Historical Financials'!G15)/DCF!$G$14 -> 67.535445 | F6: =(DCF!$B$3/(1+$A6)^1+DCF!$C$3/(1+$A6)^2+DCF!$D$3/(1+$A6)^3+DCF!$E$3/(1+$A6)^4+DCF!$F$3/(1+$A6)^5+DCF!$F$3*(1+F$3)/($A6-F$3)/(1+$A6)^5-WACC!$B$13+'Historical Financials'!G15)/DCF!$G$14 -> 71.169679 | H6: Bull reference | I6: ='Scenario Analysis'!D8 -> 0.117
A7: 0.13 | B7: =(DCF!$B$3/(1+$A7)^1+DCF!$C$3/(1+$A7)^2+DCF!$D$3/(1+$A7)^3+DCF!$E$3/(1+$A7)^4+DCF!$F$3/(1+$A7)^5+DCF!$F$3*(1+B$3)/($A7-B$3)/(1+$A7)^5-WACC!$B$13+'Historical Financials'!G15)/DCF!$G$14 -> 52.366988 | C7: =(DCF!$B$3/(1+$A7)^1+DCF!$C$3/(1+$A7)^2+DCF!$D$3/(1+$A7)^3+DCF!$E$3/(1+$A7)^4+DCF!$F$3/(1+$A7)^5+DCF!$F$3*(1+C$3)/($A7-C$3)/(1+$A7)^5-WACC!$B$13+'Historical Financials'!G15)/DCF!$G$14 -> 54.431884 | D7: =(DCF!$B$3/(1+$A7)^1+DCF!$C$3/(1+$A7)^2+DCF!$D$3/(1+$A7)^3+DCF!$E$3/(1+$A7)^4+DCF!$F$3/(1+$A7)^5+DCF!$F$3*(1+D$3)/($A7-D$3)/(1+$A7)^5-WACC!$B$13+'Historical Financials'!G15)/DCF!$G$14 -> 56.703269 | E7: =(DCF!$B$3/(1+$A7)^1+DCF!$C$3/(1+$A7)^2+DCF!$D$3/(1+$A7)^3+DCF!$E$3/(1+$A7)^4+DCF!$F$3/(1+$A7)^5+DCF!$F$3*(1+E$3)/($A7-E$3)/(1+$A7)^5-WACC!$B$13+'Historical Financials'!G15)/DCF!$G$14 -> 59.213748 | F7: =(DCF!$B$3/(1+$A7)^1+DCF!$C$3/(1+$A7)^2+DCF!$D$3/(1+$A7)^3+DCF!$E$3/(1+$A7)^4+DCF!$F$3/(1+$A7)^5+DCF!$F$3*(1+F$3)/($A7-F$3)/(1+$A7)^5-WACC!$B$13+'Historical Financials'!G15)/DCF!$G$14 -> 62.003168 | H7: Current market price | I7: =Assumptions!B3 -> 162.71
A8: 0.14 | B8: =(DCF!$B$3/(1+$A8)^1+DCF!$C$3/(1+$A8)^2+DCF!$D$3/(1+$A8)^3+DCF!$E$3/(1+$A8)^4+DCF!$F$3/(1+$A8)^5+DCF!$F$3*(1+B$3)/($A8-B$3)/(1+$A8)^5-WACC!$B$13+'Historical Financials'!G15)/DCF!$G$14 -> 47.006795 | C8: =(DCF!$B$3/(1+$A8)^1+DCF!$C$3/(1+$A8)^2+DCF!$D$3/(1+$A8)^3+DCF!$E$3/(1+$A8)^4+DCF!$F$3/(1+$A8)^5+DCF!$F$3*(1+C$3)/($A8-C$3)/(1+$A8)^5-WACC!$B$13+'Historical Financials'!G15)/DCF!$G$14 -> 48.675176 | D8: =(DCF!$B$3/(1+$A8)^1+DCF!$C$3/(1+$A8)^2+DCF!$D$3/(1+$A8)^3+DCF!$E$3/(1+$A8)^4+DCF!$F$3/(1+$A8)^5+DCF!$F$3*(1+D$3)/($A8-D$3)/(1+$A8)^5-WACC!$B$13+'Historical Financials'!G15)/DCF!$G$14 -> 50.495229 | E8: =(DCF!$B$3/(1+$A8)^1+DCF!$C$3/(1+$A8)^2+DCF!$D$3/(1+$A8)^3+DCF!$E$3/(1+$A8)^4+DCF!$F$3/(1+$A8)^5+DCF!$F$3*(1+E$3)/($A8-E$3)/(1+$A8)^5-WACC!$B$13+'Historical Financials'!G15)/DCF!$G$14 -> 52.48862 | F8: =(DCF!$B$3/(1+$A8)^1+DCF!$C$3/(1+$A8)^2+DCF!$D$3/(1+$A8)^3+DCF!$E$3/(1+$A8)^4+DCF!$F$3/(1+$A8)^5+DCF!$F$3*(1+F$3)/($A8-F$3)/(1+$A8)^5-WACC!$B$13+'Historical Financials'!G15)/DCF!$G$14 -> 54.681351 | H8: Read-through | I8: Sensitivity correctly recalculates explicit FCFF PV and terminal value at each WACC / g combination.

Sheet Comparable Companies
A1: Comparable Companies — Valuation Cross-Check
A2: Company | B2: Market cap | C2: EV | D2: P/E | E2: EV/Revenue | F2: EV/EBITDA | G2: Why comparable | H2: Source / note
A3: Motherson | B3: 169399 | C3: =B3+'Historical Financials'!G14-'Historical Financials'!G15 -> 177778 | D3: 38.7 | E3: =C3/'Historical Financials'!G3 -> 1.4097729 | F3: =C3/'Historical Financials'!G5 -> 14.774204 | G3: Subject company; global diversified auto supplier | H3: Market cap linked to Assumptions; EV = market cap + debt − cash
A4: Uno Minda | B4: 71066 | C4: 73876 | D4: 59.45 | E4: 3.58 | F4: 29.54 | G4: Indian auto-components benchmark; growth / OEM exposure | H4: INR crore; StockAnalysis, Sep 8-9 2026
A5: Forvia | B5: 21365.5 | C5: 103193.2 | E5: 0.44 | F5: 4.21 | G5: Global auto-components / cockpit / electronics exposure | H5: Converted from EUR using ECB Sep 8 2026 EUR/INR 110.1315
A6: Aptiv | B6: 90076.6 | C6: 136726.8 | D6: 21.83 | E6: 0.71 | F6: 4.48 | G6: Global electrical architecture / software supplier | H6: Converted from USD; StockAnalysis Sep 8 2026
A7: Lear | B7: 60493.6 | C7: 83344.6 | D7: 12.05 | E7: 0.37 | F7: 5.16 | G7: Seating / E-systems | H7: Converted from USD; StockAnalysis Sep 9 2026
A8: Peer median | B8: =MEDIAN(B4:B7) -> 65779.8 | C8: =MEDIAN(C4:C7) -> 93268.9 | D8: =MEDIAN(D4:D7) -> 21.83 | E8: =MEDIAN(E4:E7) -> 0.575 | F8: =MEDIAN(F4:F7) -> 4.82 | G8: Operating peer median | H8: Calculated from displayed peers
A9: Comparable-company method
A10: EV/EBITDA is the primary operating multiple; P/E is secondary.
A11: All displayed valuation amounts are normalized to INR crore; source markets may be EUR/USD.
A12: Peers are a cross-check, not a replacement for the FCFF DCF; refresh market data before publication.

Sheet Scenario Analysis
A1: Scenario Analysis — Dynamic Bear / Base / Bull
A2: Driver | B2: Bear | C2: Base | D2: Bull | E2: Units | F2: Rationale
A3: FY27 revenue growth | B3: 0.08 | C3: 0.1 | D3: 0.12 | E3: % | F3: Bear slows; base uses existing case; bull assumes stronger program wins / mix | H3: Scenario summary | I3: Value
A4: FY28 revenue growth | B4: 0.07 | C4: 0.1 | D4: 0.11 | E4: % | H4: Bear value / share | I4: =I19 -> 33.018298
A5: FY29 revenue growth | B5: 0.06 | C5: 0.09 | D5: 0.1 | E5: % | H5: Base value / share | I5: =I38 -> 62.433452
A6: FY30 revenue growth | B6: 0.05 | C6: 0.08 | D6: 0.09 | E6: % | H6: Bull value / share | I6: =I57 -> 90.827918
A7: FY31 revenue growth | B7: 0.05 | C7: 0.07 | D7: 0.08 | E7: % | H7: Current price | I7: =Assumptions!B3 -> 162.71
A8: FY31 EBITDA margin | B8: 0.098 | C8: 0.11 | D8: 0.117 | E8: % | F8: Bear modest margin recovery; bull stronger operating leverage | H8: Base DCF discount to market | I8: =DCF!G17 -> -0.61629001
A9: D&A / revenue | B9: 0.039 | C9: 0.037 | D9: 0.036 | E9: % | H9: Market EV / FY26 EBITDA | I9: =Assumptions!B16 -> 14.968033
A10: CapEx / revenue | B10: 0.05 | C10: 0.045 | D10: 0.042 | E10: %
A11: NWC / revenue | B11: 0.04 | C11: 0.035 | D11: 0.032 | E11: % | H11: Bear: slower growth, lower margins, higher reinvestment and WACC
A12: WACC | B12: 0.135 | C12: =WACC!B16 -> 0.12947461 | D12: 0.115 | E12: % | F12: Bear higher risk; base peer-derived WACC; bull lower discount rate | H12: Base: existing operating forecast + peer-derived WACC
A13: Bear Case Build | B13: 0.03 | C13: 0.04 | D13: 0.04 | E13: % | H13: Bull: stronger growth, margins and reinvestment efficiency
A14: Metric | B14: FY27E | C14: FY28E | D14: FY29E | E14: FY30E | F14: FY31E | H14: FY31 FCFF | I14: =F24 -> 5220.648
A15: Revenue | B15: =Forecast!B3*(1+B3) -> 136191.96 | C15: =B15*(1+B4) -> 145725.4 | D15: =C15*(1+B5) -> 154468.93 | E15: =D15*(1+B6) -> 162192.37 | F15: =E15*(1+B7) -> 170301.99 | H15: Terminal value | I15: =F24*(1+B13)/(B12-B13) -> 51212.071
A16: EBITDA margin | B16: =Forecast!C6 -> 0.102 | C16: =B8-(B8-Forecast!C6)*(5-1)/4 -> 0.102 | D16: =B8-(B8-Forecast!C6)*(5-2)/4 -> 0.101 | E16: =B8-(B8-Forecast!C6)*(5-3)/4 -> 0.1 | F16: =B8-(B8-Forecast!C6)*(5-4)/4 -> 0.099 | H16: PV terminal value | I16: =I15*F25 -> 27188.987
A17: EBITDA | B17: =B15*B16 -> 13891.58 | C17: =C15*C16 -> 14863.991 | D17: =D15*D16 -> 15601.361 | E17: =E15*E16 -> 16219.237 | F17: =F15*F16 -> 16859.897 | H17: Enterprise value | I17: =SUM(B26:F26)+I16 -> 43227.973
A18: D&A | B18: =B15*B9 -> 5311.4866 | C18: =C15*B9 -> 5683.2906 | D18: =D15*B9 -> 6024.2881 | E18: =E15*B9 -> 6325.5025 | F18: =F15*B9 -> 6641.7776 | H18: Equity value | I18: =I17-WACC!B13+'Historical Financials'!G15 -> 34848.973
A19: EBIT | B19: =B17-B18 -> 8580.0937 | C19: =C17-C18 -> 9180.7003 | D19: =D17-D18 -> 9577.0734 | E19: =E17-E18 -> 9893.7347 | F19: =F17-F18 -> 10218.119 | H19: Intrinsic value / share | I19: =I18/Assumptions!B15 -> 33.018298
A20: NOPAT | B20: =B19*(1-Assumptions!B10) -> 6229.148 | C20: =C19*(1-Assumptions!B10) -> 6665.1884 | D20: =D19*(1-Assumptions!B10) -> 6952.9553 | E20: =E19*(1-Assumptions!B10) -> 7182.8514 | F20: =F19*(1-Assumptions!B10) -> 7418.3547
A21: CapEx | B21: =B15*B10 -> 6809.5982 | C21: =C15*B10 -> 7286.2701 | D21: =D15*B10 -> 7723.4463 | E21: =E15*B10 -> 8109.6186 | F21: =F15*B10 -> 8515.0995
A22: NWC | B22: =B15*B11 -> 5447.6785 | C22: =C15*B11 -> 5829.016 | D22: =D15*B11 -> 6178.757 | E22: =E15*B11 -> 6487.6949 | F22: =F15*B11 -> 6812.0796
A23: Change in NWC | B23: =B22-Forecast!B12 -> 1084.6785 | C23: =C22-B22 -> 381.3375 | D23: =D22-C22 -> 349.74096 | E23: =E22-D22 -> 308.93785 | F23: =F22-E22 -> 324.38474
A24: FCFF | B24: =B20+B18-B21-B23 -> 3646.3579 | C24: =C20+C18-C21-C23 -> 4680.8715 | D24: =D20+D18-D21-D23 -> 4904.0561 | E24: =E20+E18-E21-E23 -> 5089.7974 | F24: =F20+F18-F21-F23 -> 5220.648
A25: Discount factor | B25: =1/(1+B12)^1 -> 0.88105727 | C25: =1/(1+B12)^2 -> 0.77626191 | D25: =1/(1+B12)^3 -> 0.6839312 | E25: =1/(1+B12)^4 -> 0.60258255 | F25: =1/(1+B12)^5 -> 0.53090974
A26: PV of FCFF | B26: =B24*B25 -> 3212.6501 | C26: =C24*C25 -> 3633.5822 | D26: =D24*D25 -> 3354.037 | E26: =E24*E25 -> 3067.0231 | F26: =F24*F25 -> 2771.6929
A32: Base Case Build | H32: Valuation outputs
A33: Metric | B33: FY27E | C33: FY28E | D33: FY29E | E33: FY30E | F33: FY31E | H33: FY31 FCFF | I33: =F43 -> 8208.4132
A34: Revenue | B34: =Forecast!B3*(1+C3) -> 138714.04 | C34: =B34*(1+C4) -> 152585.44 | D34: =C34*(1+C5) -> 166318.13 | E34: =D34*(1+C6) -> 179623.58 | F34: =E34*(1+C7) -> 192197.23 | H34: Terminal value | I34: =F43*(1+C13)/(C12-C13) -> 95409.751
A35: EBITDA margin | B35: =Assumptions!B21 -> 0.102 | C35: =Assumptions!C21 -> 0.104 | D35: =Assumptions!D21 -> 0.106 | E35: =Assumptions!E21 -> 0.108 | F35: =Assumptions!F21 -> 0.11 | H35: PV terminal value | I35: =I34*F44 -> 51905.145
A36: EBITDA | B36: =B34*B35 -> 14148.832 | C36: =C34*C35 -> 15868.886 | D36: =D34*D35 -> 17629.722 | E36: =E34*E35 -> 19399.347 | F36: =F34*F35 -> 21141.695 | H36: Enterprise value | I36: =SUM(B45:F45)+I35 -> 74274.029
A37: D&A | B37: =B34*C9 -> 5132.4194 | C37: =C34*C9 -> 5645.6613 | D37: =D34*C9 -> 6153.7708 | E37: =E34*C9 -> 6646.0725 | F37: =F34*C9 -> 7111.2976 | H37: Equity value | I37: =I36-WACC!B13+'Historical Financials'!G15 -> 65895.029
A38: EBIT | B38: =B36-B37 -> 9016.4124 | C38: =C36-C37 -> 10223.225 | D38: =D36-D37 -> 11475.951 | E38: =E36-E37 -> 12753.274 | F38: =F36-F37 -> 14030.398 | H38: Intrinsic value / share | I38: =I37/Assumptions!B15 -> 62.433452
A39: NOPAT | B39: =B38*(1-Assumptions!B10) -> 6545.9154 | C39: =C38*(1-Assumptions!B10) -> 7422.061 | D39: =D38*(1-Assumptions!B10) -> 8331.5404 | E39: =E38*(1-Assumptions!B10) -> 9258.8771 | F39: =F38*(1-Assumptions!B10) -> 10186.069
A40: CapEx | B40: =B34*C10 -> 6242.1317 | C40: =C34*C10 -> 6866.3448 | D40: =D34*C10 -> 7484.3159 | E40: =E34*C10 -> 8083.0611 | F40: =F34*C10 -> 8648.8754
A41: NWC | B41: =B34*C11 -> 4854.9913 | C41: =C34*C11 -> 5340.4904 | D41: =D34*C11 -> 5821.1346 | E41: =E34*C11 -> 6286.8253 | F41: =F34*C11 -> 6726.9031
A42: Change in NWC | B42: =B41-Forecast!B12 -> 491.9913 | C42: =C41-B41 -> 485.49913 | D42: =D41-C41 -> 480.64414 | E42: =E41-D41 -> 465.69077 | F42: =F41-E41 -> 440.07777
A43: FCFF | B43: =B39+B37-B40-B42 -> 4944.2118 | C43: =C39+C37-C40-C42 -> 5715.8784 | D43: =D39+D37-D40-D42 -> 6520.3512 | E43: =E39+E37-E40-E42 -> 7356.1977 | F43: =F39+F37-F40-F42 -> 8208.4132
A44: Discount factor | B44: =1/(1+C12)^1 -> 0.8853674 | C44: =1/(1+C12)^2 -> 0.78387544 | D44: =1/(1+C12)^3 -> 0.69401777 | E44: =1/(1+C12)^4 -> 0.61446071 | F44: =1/(1+C12)^5 -> 0.54402348
A45: PV of FCFF | B45: =B43*B44 -> 4377.444 | C45: =C43*C44 -> 4480.5367 | D45: =D43*D44 -> 4525.2396 | E45: =E43*E44 -> 4520.0944 | F45: =F43*F44 -> 4465.5696
...

Sheet Charts Dashboard
A1: Charts & Dashboard — Motherson DCF
A3: KPI | B3: Value | C3: Units | D3: Interpretation
A4: Current price | B4: 160.7 | C4: ₹/share | D4: Market reference
A5: DCF base value | B5: =DCF!G15 -> 62.433452 | C5: ₹/share | D5: Conservative intrinsic estimate
A6: Bull value | B6: ='Scenario Analysis'!D8 -> 0.117 | C6: ₹/share | D6: Optimistic but disciplined
A7: Bear value | B7: ='Scenario Analysis'!B8 -> 0.098 | C7: ₹/share | D7: Downside scenario
A8: Base WACC | B8: =WACC!B16 -> 0.12947461 | C8: % | D8: Primary discount rate

Sheet Sources
A1: Source Log — Data Dates Aligned to 10-Sep-2026
A2: Source | B2: Document / page | C2: Date | D2: Use in model | E2: Link / identifier
A3: Samvardhana Motherson International Ltd | B3: FY26 audited consolidated financial results | C3: 20-May-2026 | D3: FY26 revenue, EBITDA, PAT, D&A, cash, borrowings, working capital, CFO, CapEx | E3: motherson.com / NSE filing
A4: Samvardhana Motherson International Ltd | B4: FY26 results presentation | C4: 20-May-2026 | D4: FY26 reported EBITDA ₹12,033cr and revenue ₹126,104cr | E4: motherson.com
A5: NSE India | B5: Integrated Filing — IndAS, FY26 audited | C5: 20-May-2026 | D5: Audited consolidated financial statement reference | E5: nseindia.com
A6: StockAnalysis / FT | B6: MOTHERSON market data | C6: 10-Sep-2026 | D6: Share price ₹162.71; market valuation / beta cross-check | E6: stockanalysis.com / markets.ft.com
A7: Reuters / Investing.com | B7: India 10Y government bond yield | C7: 09-10-Sep-2026 | D7: Risk-free rate ~6.96% | E7: reuters.com / investing.com
A8: Aswath Damodaran / NYU | B8: Country risk premium dataset | C8: Current Sep-2026 | D8: India ERP | E8: pages.stern.nyu.edu
A9: FT / StockAnalysis | B9: Uno Minda | C9: 09-Sep-2026 | D9: Peer beta / D-E for bottom-up beta | E9: markets.ft.com / stockanalysis.com
A10: StockAnalysis | B10: Aptiv | C10: 09-Sep-2026 | D10: Peer beta / D-E for bottom-up beta | E10: stockanalysis.com
A11: StockAnalysis | B11: Lear | C11: 04-10-Sep-2026 | D11: Peer beta / D-E / tax for bottom-up beta | E11: stockanalysis.com
A12: StockAnalysis | B12: Forvia | C12: 04-Sep-2026 | D12: Peer beta / D-E for bottom-up beta | E12: stockanalysis.com

Sheet Checks
A1: Model Integrity Checks
A2: Check | B2: Result | C2: Status | D2: Comment
A3: Terminal growth < WACC | B3: =Assumptions!B11<WACC!B16 -> TRUE | C3: =IF(B3,"PASS","FAIL") -> PASS | D3: 4.0% < ~12.5%
A4: EV less debt plus cash equals equity | B4: =DCF!G10-DCF!G11+DCF!G12-DCF!G13 -> 0 | C4: =IF(ABS(B4)<0.01,"PASS","FAIL") -> PASS | D4: DCF bridge
A5: Shares outstanding > 0 | B5: =DCF!G14 -> 1055.4443 | C5: =IF(B5>0,"PASS","FAIL") -> PASS | D5: Derived from market cap / price
A6: Debt / cash consistency | B6: =Assumptions!B4-(Assumptions!B3*Assumptions!B15) -> 0 | C6: =IF(ABS(B6)<0.01,"PASS","FAIL") -> PASS | D6: Market cap equals price × shares outstanding
A7: Sensitivity values finite | B7: =COUNT(Sensitivity!B4:F8) -> 25 | C7: =IF(B7=25,"PASS","FAIL") -> PASS | D7: All WACC/g cells populated
A8: Historical balance-sheet full-check | B8: N/A | C8: LIMITATION | D8: Workbook uses selected operating items rather than a full 3-statement balance sheet
A9: Bottom-up beta | B9: =WACC!B27 -> 0.91882648 | C9: =IF(AND(B9>0,B9<3),"PASS","REVIEW") -> PASS | D9: Peer-derived median unlevered beta, relevered to Motherson market D/E
A10: Base DCF market-price bridge | B10: =DCF!G15-Assumptions!B3 -> -100.27655 | C10: =IF(ISNUMBER(B10),"PASS","FAIL") -> PASS | D10: Intrinsic value per share less current price
A11: Base scenario ties to DCF | B11: ='Scenario Analysis'!I38-DCF!G15 -> 0 | C11: =IF(ABS(B11)<0.01,"PASS","FAIL") -> PASS | D11: Scenario base value should equal primary DCF

Sheet Update Log
A1: Correction | B1: Old | C1: Updated | D1: Status
A2: FY26 cash & equivalents | B2: 5643 | C2: 7516 | D2: Fixed
A3: FY26 operating cash flow | B3: 6286 | C3: 11284 | D3: Fixed
A4: FY26 reported EBITDA | B4: 12124 | C4: 12033 | D4: Fixed
A5: FY26 operating NWC | B5: 4413.64 | C5: 4363 | D5: Fixed
A6: Shares outstanding (crore) | B6: 1054.1319 | C6: 1055.4443 | D6: Fixed
A7: Uno Minda market cap (₹ crore) | B7: 714702 | C7: 71066 | D7: Fixed
A8: Uno Minda EV (₹ crore) | B8: 742805 | C8: 73876 | D8: Fixed
A9: Primary beta | B9: 0.85 | C9: 0.85 | D9: Retained but explicitly labelled analyst assumption
A10: Terminal growth | B10: 0.04 | C10: 0.04 | D10: Retained; explicitly labelled analyst assumption
A11: Exit multiple cross-check | B11: Primary-looking output | C11: Non-primary sanity check | D11: Clarified
A12: FY26 EBITDA | B12: 12124 | C12: 12033 | D12: Fixed
A13: FY26 D&A | B13: 5000 | C13: 5133.85 | D13: Fixed
A14: Market price / cap | B14: 160.7 | C14: =Assumptions!B3 -> 162.71 | D14: Updated to 10-Sep-2026 snapshot and linked to shares
A15: Primary beta | B15: 0.85 | C15: =WACC!B27 -> 0.91882648 | D15: Replaced analyst-only beta with peer-derived bottom-up beta
A16: Scenario Analysis | B16: Hardcoded outputs | C16: Dynamic forecast / DCF | D16: Rebuilt
A17: Sensitivity table | B17: Used base-WACC PV of FCFF inside every sensitivity cell | C17: Each cell now recalculates explicit FCFF PV and terminal value using its row WACC | D17: Fixed
A18: Market-implied EV / FY26 EBITDA | B18: Debt / cash / EBITDA partly hardcoded | C18: Linked to audited FY26 borrowings, cash and EBITDA | D18: Fixed
A19: Comparable companies | B19: Motherson EV and EV/EBITDA not calculated | C19: Linked dynamically; peer median added | D19: Enhanced
A20: Model integrity checks | B20: Several PASS labels were hardcoded | C20: Status fields now evaluate formulas | D20: Enhanced
A21: WACC debt | B21: FY26 borrowings hardcoded in WACC | C21: Linked to Historical Financials FY26 borrowings | D21: Enhanced
